Workbook

Sheet Penn State Extension - ReadMe
A2: Customized Dairy Heifer Growth Chart
A3: Extension Team: | C3: Dairy | G3: Tool Version: | I3: metric units
A4: Author: | C4: Coleen Jones, Jud Heinrichs | G4: Last Updated: | I4: 42613
A5: Contact Email: | C5: cmj11@psu.edu
A6: Website: | C6: http://extension.psu.edu/animals/dairy
A7: Description:
A8: This spreadsheet is a tool designed to allow you to develop a growth curve for your heifers that is based on your goals for age at first calving. Calculations are based off of the mature size of animals in your herd and use the target growth system described in the 2001 Nutrient Requirements of Dairy Cattle.
A9: User Instructions:
A10: Required Input (enter on the INPUT section of the CALCULATIONS worksheet)
A11: Average body weight and height of cows in third lactation in your herd. Do not include cull cows in this average, as they often have poor body condition that is not representative of average cows in the herd. Either withers or hip height can be used.
A12: Average birth weight of calves.
A13: Goal for average daily gain before weaning; entered either as the number of days to double birth weight or as a specific ADG goal.
A14: Average services per conception for heifers
A15: Goal for age at first calving
A16: From this information the spreadsheet calculates the following
A17: The OUTPUT section of the Calculations worksheet, including the age and body weight at which heifer breeding should begin; age and size of heifers at conception and the average daily gain required from 2 months of age to conception; and size at calving and the average daily gain required from conception to calving.
A18: Assumptions for body weight targets are 55% of mature weight at first conception and 85% of mature weight after first calving, as cited in the 2001 Dairy NRC. Height targets are assumed to be 55% of mature height at birth and 96% of mature height at first calving; 50% of height growth from birth to calving is assumed to occur between birth and 6 months with an additional 25% between 6 and 12 months and the final 25% between 12 months and calving. These targets were derived from a comparison of heifer growth data from all breeds to mature heights calculated by assuming mature body weight and using the relationship between withers height and body weight determined by Heinrichs et al., 1992 (J Dairy Sci 75:3576-3581) and from Kertz et al., 1998 (J Dairy Sci 81:1479-1482). Withers and hip height are assumed to change at the same rate throughout the growing period, meaning either one can be used to monitor growth as long as the same measurement is used for heifers and mature cows.
... A26: This tool is provided for general informational purposes only and The Pennsylvania State University shall have no liability whatsoever for the use of or reliance on this tool.

Sheet Calculations
A2: Customized Dairy Heifer Growth Chart
A3: based on mature size and goal for age at first calving
A5: INPUT
A6: Average Size of 3rd Lactation Cows: | E6: BW (kg): | F6: 780 | G6: Ht (cm): | H6: 147
A8: Average Birth Weight of Calves (kg): | F8: 41 | H8: =H6*0.55 -> 80.85
A10: Preweaning Growth Goal:
A11: Double birth weight by __ days of age: | F11: 80
A12: OR Enter desired ADG (g/d): | F12: 0
A14: Average services per conception for heifers: | F14: 1.5
A16: Goal for AFC (mo): | F16: 22
A19: OUTPUT
A20: Calf BW at 2 months of age (kg): | G20: =IF(F12>0,((F12/1000)*60.8736)+F8,(((F8/F11)*60.8736)+F8)) -> 72.19772
A21: ADG from birth to 2 mo (g/d): | G21: =((G20-F8)/60.8736)*1000 -> 512.5
A23: Age to begin breeding heifers (mo): | G23: =G24/30.4368 -> 11.765678
A24: Age to begin breeding heifers (d): | G24: =G31-(21*F14) -> 358.1096
A25: BW to begin breeding (kg): | G25: =G32-((G33/1000)*(21*F14)) -> 394.81064
A26: If heifers do not reach breeding BW by breeding age, increase ADG before breeding
A27: If heifers reach breeding BW well before targeted breeding age, consider reducing AFC
A28: Breeding Holstein heifers before 12 months of age is NOT RECOMMENDED
A30: Age of heifers at first conception (mo): | G30: =G31/30.4368 -> 12.80061
A31: Age of heifers at first conception (d): | G31: =(F16*30.4368)-280 -> 389.6096
A32: Size of heifers at first conception: | F32: BW (kg): | G32: =F6*0.55 -> 429 | H32: Ht (cm): | I32: =0.85*H6 -> 124.95
A33: ADG required from 2 mo to conception (g/d): | G33: =((G32-G20)/(G31-60.8736))*1000 -> 1085.3764 | I33: =(I32-H8)/G31 -> 0.11319023
A35: BW 1 week before calving (kg): | G35: =((73.195*(F8/45))+G36) -> 729.68878
A36: Size after calving: | F36: BW (kg): | G36: =0.85*F6 -> 663 | H36: Ht (cm): | I36: =0.96*H6 -> 141.12
A37: ADG required from conception to calving (g/d): | G37: =((G35-G32)/((F16*30.4368)-G31))*1000 -> 1073.8885 | I37: =(I36-I32)/((F16*30.4368)-G31) -> 0.05775
A39: ADG = Average Daily Gain
A40: AFC = Age at First Calving
A41: BW = Body Weight
A42: MBW = Mature Body Weight
A43: Ht = Height, use withers or hip, just use the same one for heifers and mature cows
A44: MHt = Mature Height

Sheet Custom Table
A2: Customized Heifer Growth Chart
A3: Based on Mature Size and Goal for Age at First Calving
A5: Age, mo | B5: Age, d | C5: BW, kg | D5: % MBW | E5: Ht, cm | F5: % MHt
A6: 0 | B6: =A6*30.4368 -> 0 | C6: =Calculations!F8 -> 41 | D6: =C6/Calculations!$F$6*100 -> 5.2564103 | E6: =Calculations!H8 -> 80.85 | F6: =E6/Calculations!$H$6*100 -> 55
A7: 1 | B7: =A7*30.4368 -> 30.4368 | C7: =C6+((Calculations!G21/1000)*30.4368) -> 56.59886 | D7: =C7/Calculations!$F$6*100 -> 7.2562641 | E7: =E6+($C$49*30.4368) -> 85.8725 | F7: =E7/Calculations!$H$6*100 -> 58.416667
A8: 2 | B8: =A8*30.4368 -> 60.8736 | C8: =C7+((Calculations!G21/1000)*30.4368) -> 72.19772 | D8: =C8/Calculations!$F$6*100 -> 9.2561179 | E8: =E7+($C$49*30.4368) -> 90.895 | F8: =E8/Calculations!$H$6*100 -> 61.833333
A9: 3 | B9: =A9*30.4368 -> 91.3104 | C9: =IF(B9>Calculations!$G$31,(C8+((Calculations!$G$37/1000)*30.4368)),(C8+((Calculations!$G$33/1000)*30.4368))) -> 105.2331 | D9: =C9/Calculations!$F$6*100 -> 13.491423 | E9: =E8+($C$49*30.4368) -> 95.9175 | F9: =E9/Calculations!$H$6*100 -> 65.25
A10: 4 | B10: =A10*30.4368 -> 121.7472 | C10: =IF(B10>Calculations!$G$31,(C9+((Calculations!$G$37/1000)*30.4368)),(C9+((Calculations!$G$33/1000)*30.4368))) -> 138.26849 | D10: =C10/Calculations!$F$6*100 -> 17.726729 | E10: =E9+($C$49*30.4368) -> 100.94 | F10: =E10/Calculations!$H$6*100 -> 68.666667
A11: 5 | B11: =A11*30.4368 -> 152.184 | C11: =IF(B11>Calculations!$G$31,(C10+((Calculations!$G$37/1000)*30.4368)),(C10+((Calculations!$G$33/1000)*30.4368))) -> 171.30387 | D11: =C11/Calculations!$F$6*100 -> 21.962034 | E11: =E10+($C$49*30.4368) -> 105.9625 | F11: =E11/Calculations!$H$6*100 -> 72.083333
A12: 6 | B12: =A12*30.4368 -> 182.6208 | C12: =IF(B12>Calculations!$G$31,(C11+((Calculations!$G$37/1000)*30.4368)),(C11+((Calculations!$G$33/1000)*30.4368))) -> 204.33925 | D12: =C12/Calculations!$F$6*100 -> 26.19734 | E12: =E11+($C$49*30.4368) -> 110.985 | F12: =E12/Calculations!$H$6*100 -> 75.5
A13: 7 | B13: =A13*30.4368 -> 213.0576 | C13: =IF(B13>Calculations!$G$31,(C12+((Calculations!$G$37/1000)*30.4368)),(C12+((Calculations!$G$33/1000)*30.4368))) -> 237.37463 | D13: =C13/Calculations!$F$6*100 -> 30.432645 | E13: =E12+($C$50*30.4368) -> 113.49625 | F13: =E13/Calculations!$H$6*100 -> 77.208333
A14: 8 | B14: =A14*30.4368 -> 243.4944 | C14: =IF(B14>Calculations!$G$31,(C13+((Calculations!$G$37/1000)*30.4368)),(C13+((Calculations!$G$33/1000)*30.4368))) -> 270.41002 | D14: =C14/Calculations!$F$6*100 -> 34.667951 | E14: =E13+($C$50*30.4368) -> 116.0075 | F14: =E14/Calculations!$H$6*100 -> 78.916667
A15: 9 | B15: =A15*30.4368 -> 273.9312 | C15: =IF(B15>Calculations!$G$31,(C14+((Calculations!$G$37/1000)*30.4368)),(C14+((Calculations!$G$33/1000)*30.4368))) -> 303.4454 | D15: =C15/Calculations!$F$6*100 -> 38.903256 | E15: =E14+($C$50*30.4368) -> 118.51875 | F15: =E15/Calculations!$H$6*100 -> 80.625
A16: 10 | B16: =A16*30.4368 -> 304.368 | C16: =IF(B16>Calculations!$G$31,(C15+((Calculations!$G$37/1000)*30.4368)),(C15+((Calculations!$G$33/1000)*30.4368))) -> 336.48078 | D16: =C16/Calculations!$F$6*100 -> 43.138562 | E16: =E15+($C$50*30.4368) -> 121.03 | F16: =E16/Calculations!$H$6*100 -> 82.333333
A17: 11 | B17: =A17*30.4368 -> 334.8048 | C17: =IF(B17>Calculations!$G$31,(C16+((Calculations!$G$37/1000)*30.4368)),(C16+((Calculations!$G$33/1000)*30.4368))) -> 369.51617 | D17: =C17/Calculations!$F$6*100 -> 47.373867 | E17: =E16+($C$50*30.4368) -> 123.54125 | F17: =E17/Calculations!$H$6*100 -> 84.041667
A18: 12 | B18: =A18*30.4368 -> 365.2416 | C18: =IF(B18>Calculations!$G$31,(C17+((Calculations!$G$37/1000)*30.4368)),(C17+((Calculations!$G$33/1000)*30.4368))) -> 402.55155 | D18: =C18/Calculations!$F$6*100 -> 51.609173 | E18: =E17+($C$50*30.4368) -> 126.0525 | F18: =E18/Calculations!$H$6*100 -> 85.75
A19: 13 | B19: =A19*30.4368 -> 395.6784 | C19: =IF(B19>Calculations!$G$31,(C18+((Calculations!$G$37/1000)*30.4368)),(C18+((Calculations!$G$33/1000)*30.4368))) -> 435.23728 | D19: =C19/Calculations!$F$6*100 -> 55.799651 | E19: =E18+($C$51*30.4368) -> 127.55925 | F19: =E19/Calculations!$H$6*100 -> 86.775
A20: 14 | B20: =A20*30.4368 -> 426.1152 | C20: =IF(B20>Calculations!$G$31,(C19+((Calculations!$G$37/1000)*30.4368)),(C19+((Calculations!$G$33/1000)*30.4368))) -> 467.92301 | D20: =C20/Calculations!$F$6*100 -> 59.990129 | E20: =E19+($C$51*30.4368) -> 129.066 | F20: =E20/Calculations!$H$6*100 -> 87.8
A21: 15 | B21: =A21*30.4368 -> 456.552 | C21: =IF(B21>Calculations!$G$31,(C20+((Calculations!$G$37/1000)*30.4368)),(C20+((Calculations!$G$33/1000)*30.4368))) -> 500.60874 | D21: =C21/Calculations!$F$6*100 -> 64.180607 | E21: =E20+($C$51*30.4368) -> 130.57275 | F21: =E21/Calculations!$H$6*100 -> 88.825
A22: 16 | B22: =A22*30.4368 -> 486.9888 | C22: =IF(B22>Calculations!$G$31,(C21+((Calculations!$G$37/1000)*30.4368)),(C21+((Calculations!$G$33/1000)*30.4368))) -> 533.29447 | D22: =C22/Calculations!$F$6*100 -> 68.371085 | E22: =E21+($C$51*30.4368) -> 132.0795 | F22: =E22/Calculations!$H$6*100 -> 89.85
A23: 17 | B23: =A23*30.4368 -> 517.4256 | C23: =IF(B23>Calculations!$G$31,(C22+((Calculations!$G$37/1000)*30.4368)),(C22+((Calculations!$G$33/1000)*30.4368))) -> 565.9802 | D23: =C23/Calculations!$F$6*100 -> 72.561564 | E23: =E22+($C$51*30.4368) -> 133.58625 | F23: =E23/Calculations!$H$6*100 -> 90.875
A24: 18 | B24: =A24*30.4368 -> 547.8624 | C24: =IF(B24>$E$37,(Calculations!$G$36+(($E$41/1000)*(B24-$E$37))),(C23+((Calculations!$G$37/1000)*30.4368))) -> 598.66592 | D24: =C24/Calculations!$F$6*100 -> 76.752042 | E24: =IF(B24>$E$37,(E23+($F$41*30.4368)),(E23+($C$51*30.4368))) -> 135.093 | F24: =E24/Calculations!$H$6*100 -> 91.9
A25: 19 | B25: =A25*30.4368 -> 578.2992 | C25: =IF(B25>$E$37,(Calculations!$G$36+(($E$41/1000)*(B25-$E$37))),(C24+((Calculations!$G$37/1000)*30.4368))) -> 631.35165 | D25: =C25/Calculations!$F$6*100 -> 80.94252 | E25: =IF(B25>$E$37,(E24+($F$41*30.4368)),(E24+($C$51*30.4368))) -> 136.59975 | F25: =E25/Calculations!$H$6*100 -> 92.925
A26: 20 | B26: =A26*30.4368 -> 608.736 | C26: =IF(B26>$E$37,(Calculations!$G$36+(($E$41/1000)*(B26-$E$37))),(C25+((Calculations!$G$37/1000)*30.4368))) -> 664.03738 | D26: =C26/Calculations!$F$6*100 -> 85.132998 | E26: =IF(B26>$E$37,(E25+($F$41*30.4368)),(E25+($C$51*30.4368))) -> 138.1065 | F26: =E26/Calculations!$H$6*100 -> 93.95
A27: 21 | B27: =A27*30.4368 -> 639.1728 | C27: =IF(B27>$E$37,(Calculations!$G$36+(($E$41/1000)*(B27-$E$37))),(C26+((Calculations!$G$37/1000)*30.4368))) -> 696.72311 | D27: =C27/Calculations!$F$6*100 -> 89.323476 | E27: =IF(B27>$E$37,(E26+($F$41*30.4368)),(E26+($C$51*30.4368))) -> 139.61325 | F27: =E27/Calculations!$H$6*100 -> 94.975
A28: 22 | B28: =A28*30.4368 -> 669.6096 | C28: =IF(B28>$E$37,(Calculations!$G$36+(($E$41/1000)*(B28-$E$37))),(C27+((Calculations!$G$37/1000)*30.4368))) -> 729.40884 | D28: =C28/Calculations!$F$6*100 -> 93.513954 | E28: =IF(B28>$E$37,(E27+($F$41*30.4368)),(E27+($C$51*30.4368))) -> 141.12 | F28: =E28/Calculations!$H$6*100 -> 96
A29: 23 | B29: =A29*30.4368 -> 700.0464 | C29: =IF(B29>$E$37,(Calculations!$G$36+(($E$41/1000)*(B29-$E$37))),(C28+((Calculations!$G$37/1000)*30.4368))) -> 672.14006 | D29: =C29/Calculations!$F$6*100 -> 86.171803 | E29: =IF(B29>$E$37,(E28+($F$41*30.4368)),(E28+($C$51*30.4368))) -> 141.22889 | F29: =E29/Calculations!$H$6*100 -> 96.074074
A30: 24 | B30: =A30*30.4368 -> 730.4832 | C30: =IF(B30>$E$37,(Calculations!$G$36+(($E$41/1000)*(B30-$E$37))),(C29+((Calculations!$G$37/1000)*30.4368))) -> 681.28013 | D30: =C30/Calculations!$F$6*100 -> 87.343606 | E30: =IF(B30>$E$37,(E29+($F$41*30.4368)),(E29+($C$51*30.4368))) -> 141.33778 | F30: =E30/Calculations!$H$6*100 -> 96.148148
A31: 25 | B31: =A31*30.4368 -> 760.92 | C31: =IF(B31>$E$37,(Calculations!$G$36+(($E$41/1000)*(B31-$E$37))),(C30+((Calculations!$G$37/1000)*30.4368))) -> 690.42019 | D31: =C31/Calculations!$F$6*100 -> 88.515409 | E31: =IF(B31>$E$37,(E30+($F$41*30.4368)),(E30+($C$51*30.4368))) -> 141.44667 | F31: =E31/Calculations!$H$6*100 -> 96.222222
A32: 26 | B32: =A32*30.4368 -> 791.3568 | C32: =IF(B32>$E$37,(Calculations!$G$36+(($E$41/1000)*(B32-$E$37))),(C31+((Calculations!$G$37/1000)*30.4368))) -> 699.56025 | D32: =C32/Calculations!$F$6*100 -> 89.687212 | E32: =IF(B32>$E$37,(E31+($F$41*30.4368)),(E31+($C$51*30.4368))) -> 141.55556 | F32: =E32/Calculations!$H$6*100 -> 96.296296
A33: 27 | B33: =A33*30.4368 -> 821.7936 | C33: =IF(B33>$E$37,(Calculations!$G$36+(($E$41/1000)*(B33-$E$37))),(C32+((Calculations!$G$37/1000)*30.4368))) -> 708.70032 | D33: =C33/Calculations!$F$6*100 -> 90.859015 | E33: =IF(B33>$E$37,(E32+($F$41*30.4368)),(E32+($C$51*30.4368))) -> 141.66444 | F33: =E33/Calculations!$H$6*100 -> 96.37037
A34: 28 | B34: =A34*30.4368 -> 852.2304 | C34: =IF(B34>$E$37,(Calculations!$G$36+(($E$41/1000)*(B34-$E$37))),(C33+((Calculations!$G$37/1000)*30.4368))) -> 717.84038 | D34: =C34/Calculations!$F$6*100 -> 92.030818 | E34: =IF(B34>$E$37,(E33+($F$41*30.4368)),(E33+($C$51*30.4368))) -> 141.77333 | F34: =E34/Calculations!$H$6*100 -> 96.444444
A37: AFC (d): | E37: =Calculations!F16*30.4368 -> 669.6096
A38: BW post 2nd calving (kg): | E38: =Calculations!F6*0.92 -> 717.6 | F38: =0.97*Calculations!H6 -> 142.59 | G38: Height
A39: BW 7 d before 2nd calving (kg): | E39: =(73.195*(Calculations!F8/45))+E38 -> 784.28878
A40: Calving interval (mo): | E40: 13.5
A41: ADG required during 1st lacation (g/d): | E41: =(('Custom Table'!E39-Calculations!G36)/(('Custom Table'!E40*30.4368)-7))*1000 -> 300.29646 | F41: =('Custom Table'!F38-Calculations!I36)/('Custom Table'!E40*30.4368) -> 0.0035775406 | G41: Height
A43: Height Targets
A44: At calving | B44: =Calculations!I36 -> 141.12
A45: At birth | B45: =Calculations!H8 -> 80.85
...

Sheet Input Heifer Data
A1: id | B1: birth_date | C1: date | D1: weight_kg | E1: mature_weight | F1: height_cm | G1: mature_height | H1: Age (mo) | I1: % MBW | J1: %MHt
A2: 10089 | B2: 27/08/2025 | C2: 46148 | D2: 289 | E2: 780 | F2: 130.81 | G2: 152.4 | H2: 8.2867478 | I2: =D2/E2*100 -> 37.051282 | J2: =F2/G2*100 -> 85.833333
A3: 10094 | B3: 28/08/2025 | C3: 46148 | D3: 281 | E3: 780 | F3: 127.635 | G3: 152.4 | H3: 8.2538639 | I3: =D3/E3*100 -> 36.025641 | J3: =F3/G3*100 -> 83.75
A4: 10104 | B4: 31/08/2025 | C4: 46148 | D4: 287 | E4: 780 | F4: 135.255 | G4: 152.4 | H4: 8.1552121 | I4: =D4/E4*100 -> 36.794872 | J4: =F4/G4*100 -> 88.75
A5: 10106 | B5: 1/ 9/25 | C5: 46148 | D5: 249 | E5: 780 | F5: 132.715 | G5: 152.4 | H5: 8.1223282 | I5: =D5/E5*100 -> 31.923077 | J5: =F5/G5*100 -> 87.083333
A6: 10107 | B6: 1/ 9/25 | C6: 46148 | D6: 286 | E6: 780 | F6: 133.985 | G6: 152.4 | H6: 8.1223282 | I6: =D6/E6*100 -> 36.666667 | J6: =F6/G6*100 -> 87.916667
A7: 10108 | B7: 2/ 9/25 | C7: 46148 | D7: 232 | E7: 780 | F7: 131.445 | G7: 152.4 | H7: 8.0894443 | I7: =D7/E7*100 -> 29.74359 | J7: =F7/G7*100 -> 86.25
A8: 10109 | B8: 2/ 9/25 | C8: 46148 | D8: 291 | E8: 780 | F8: 132.08 | G8: 152.4 | H8: 8.0894443 | I8: =D8/E8*100 -> 37.307692 | J8: =F8/G8*100 -> 86.666667
A9: 10110 | B9: 2/ 9/25 | C9: 46148 | D9: 267 | E9: 780 | F9: 132.08 | G9: 152.4 | H9: 8.0894443 | I9: =D9/E9*100 -> 34.230769 | J9: =F9/G9*100 -> 86.666667
A10: 10111 | B10: 2/ 9/25 | C10: 46148 | D10: 267 | E10: 780 | F10: 132.08 | G10: 152.4 | H10: 8.0894443 | I10: =D10/E10*100 -> 34.230769 | J10: =F10/G10*100 -> 86.666667
A11: 10112 | B11: 3/ 9/25 | C11: 46148 | D11: 314 | E11: 780 | F11: 128.905 | G11: 152.4 | H11: 8.0565603 | I11: =D11/E11*100 -> 40.25641 | J11: =F11/G11*100 -> 84.583333
A12: 10113 | B12: 3/ 9/25 | C12: 46148 | D12: 306 | E12: 780 | F12: 135.255 | G12: 152.4 | H12: 8.0565603 | I12: =D12/E12*100 -> 39.230769 | J12: =F12/G12*100 -> 88.75
A13: 10114 | B13: 3/ 9/25 | C13: 46148 | D13: 290 | E13: 780 | F13: 133.35 | G13: 152.4 | H13: 8.0565603 | I13: =D13/E13*100 -> 37.179487 | J13: =F13/G13*100 -> 87.5
... A56: 10164 | B56: 23/ 9/25 | C56: 46148 | D56: 278 | E56: 780 | F56: 135.89 | G56: 152.4 | H56: 7.3988819 | I56: =D56/E56*100 -> 35.641026 | J56: =F56/G56*100 -> 89.166667
A57: 10165 | B57: 23/ 9/25 | C57: 46148 | D57: 295 | E57: 780 | H57: 7.3988819
A58: 10166 | B58: 23/ 9/25 | C58: 46148 | D58: 256 | E58: 780 | H58: 7.3988819
A59: 10167 | B59: 23/ 9/25 | C59: 46148 | D59: 302 | E59: 780 | H59: 7.3988819
A60: 10168 | B60: 23/ 9/25 | C60: 46148 | D60: 298 | E60: 780 | H60: 7.3988819
A61: 10170 | B61: 25/ 9/25 | C61: 46148 | D61: 257 | E61: 780 | H61: 7.3331141
A62: 10171 | B62: 25/ 9/25 | C62: 46148 | D62: 281 | E62: 780 | H62: 7.3331141
A63: 10172 | B63: 27/ 9/25 | C63: 46148 | D63: 240 | E63: 780 | H63: 7.2673463
A64: 10173 | B64: 28/ 9/25 | C64: 46148 | D64: 300 | E64: 780 | H64: 7.2344623
A65: 10236 | B65: 22/10/25 | C65: 46148 | D65: 242 | E65: 780 | H65: 6.4452483
A66: 94789 | B66: 25/ 3/25 | C66: 46148 | D66: 341 | E66: 780 | H66: 13.383755
A67: 94794 | B67: 27/ 3/25 | C67: 46148 | D67: 427 | E67: 780 | H67: 13.317988
A68: 94795 | B68: 27/ 3/25 | C68: 46148 | D68: 380 | E68: 780 | H68: 13.317988
... A214: 94988 | B214: 18/ 7/25 | C214: 46148 | D214: 319 | E214: 780 | H214: 9.6021046
